# python 中的 try-catch-finally-else 简介

```python
try：
  code    #需要判断是否会抛出异常的代码，如果没有异常处理，python会直接停止执行程序

except:  #这里会捕捉到上面代码中的异常，并根据异常抛出异常处理信息
#except ExceptionName，args：    #同时也可以接受异常名称和参数，针对不同形式的异常做处理

  code  #这里执行异常处理的相关代码，打印输出等

else：  #如果没有异常则执行else

  code  #try部分被正常执行后执行的代码

finally：
  code  #退出try语句块总会执行的程序
```

可以看到，

1. 这里的 else 是和 trycatch 连用的，并且 else 只在 try 中代码没有异常的情况下执行，else 必须在 except 这句代码存在的时候才能出现。

2.finally 这个片段里面的代码是肯定在最后执行的，无论前面是否发生异常，最后总会执行 finally 片段内的代码。

所以，正常的流程是：try 没有发生错误 -》else 内的代码 -》finally 中的代码。

发生异常的流程是：try 中发生异常 -》被 except 捕获并执行 except 片段中的代码 -》执行 finally 中的代码。

## try...except...

```python
try :
...执行代码...
except 异常类型 as 变量名:
...执行异常...
```

   

## try...else...



if...else...，在 if 中，它的作用是当条件不满足时执行的实行，在 try...except... 中也是如此，即如果没有捕获到异常，那么就执行 else 中的事情

## try...finally...

try...finally... 语句用来表达这样的情况：

在程序中，如果一个段代码必须要执行，即无论异常是否产生都要执行，那么此时就需要使用 finally。 比如文件关闭，释放锁，把数据库连接返还给连接池等。

说明：不管 try 语句有没有执行成功，都会执行 finally 当中的代码段

## raise 抛出系统异常

你可以用 raise 语句来引发一个异常，异常 / 错误对象必须有一个名字，且它们应是 Error 或 Exception 类的子类

```python
raise 手动捕获异常
```

如果 try 代码块可能出现多种错误类型，可以编写多个 except 代码块来处理；此外，如果没有发生错误，还可以在 except 代码块后面加上 else 语句，当没有错误的时候，会自动执行 else 语句：

```python
>>> try:
...     print('开始：')
...     r = 10 / int('2')
...     print('结果：',r)
... except ValueError as e:
...     print('ValueError:',e)
... except ZeroDivisionError as e:
...     print('ZeroDivision:',r)
... else:
...     print('没有出错！')
... finally:
...     print('最后要执行的代码')
...
开始：
结果： 5.0
没有出错！
最后要执行的代码
```

万物皆对象，python 的错误也是 class，所有的错误类型都继承自 BaseException，各个类型的错误之间可能会存在继承关系，比如 UnicodeError 是 ValueError 的子类，如果 catch 语句中同时出现了这两个错误，且 UnicodeError 在 ValueError 的后面处理的，那么永远都捕获不到 UnicodeError。

下面是 python 中内置的常用错误类型继承关系：

```python
BaseException
 +-- SystemExit
 +-- KeyboardInterrupt
 +-- GeneratorExit
 +-- Exception
      +-- StopIteration
      +-- StopAsyncIteration
      +-- ArithmeticError
      |    +-- FloatingPointError
      |    +-- OverflowError
      |    +-- ZeroDivisionError
      +-- AssertionError
      +-- AttributeError
      +-- BufferError
      +-- EOFError
      +-- ImportError
      |    +-- ModuleNotFoundError
      +-- LookupError
      |    +-- IndexError
      |    +-- KeyError
      +-- MemoryError
      +-- NameError
      |    +-- UnboundLocalError
      +-- OSError
      |    +-- BlockingIOError
      |    +-- ChildProcessError
      |    +-- ConnectionError
      |    |    +-- BrokenPipeError
      |    |    +-- ConnectionAbortedError
      |    |    +-- ConnectionRefusedError
      |    |    +-- ConnectionResetError
      |    +-- FileExistsError
      |    +-- FileNotFoundError
      |    +-- InterruptedError
      |    +-- IsADirectoryError
      |    +-- NotADirectoryError
      |    +-- PermissionError
      |    +-- ProcessLookupError
      |    +-- TimeoutError
      +-- ReferenceError
      +-- RuntimeError
      |    +-- NotImplementedError
      |    +-- RecursionError
      +-- SyntaxError
      |    +-- IndentationError
      |         +-- TabError
      +-- SystemError
      +-- TypeError
      +-- ValueError
      |    +-- UnicodeError
      |         +-- UnicodeDecodeError
      |         +-- UnicodeEncodeError
      |         +-- UnicodeTranslateError
      +-- Warning
           +-- DeprecationWarning
           +-- PendingDeprecationWarning
           +-- RuntimeWarning
           +-- SyntaxWarning
           +-- UserWarning
           +-- FutureWarning
           +-- ImportWarning
           +-- UnicodeWarning
           +-- BytesWarning
           +-- ResourceWarning
```

使用 try…catch… 捕获错误一个好处就是，可以跨层调用，比如 main () 调用 foo ()，foo () 调用 bar ()，而错误是在 bar 中出现的，最后我们只需要在 main () 中捕获就行：

```python
>>> def foo(s):
...     return 10 / int(s)
...
>>> def bar(s):
...     return foo(s)*2
...
>>> def main():
...     try:
...             bar('0')
...     except Exception as e:
...             print('Error:',e)
...     finally:
...             print('最终要执行的代码')
...
>>> main()
Error: division by zero
最终要执行的代码
```

调用栈

如果没有捕捉错误，该错误就会一直往上抛，最后被 python 解释器捕获，并打印一条错误消息，然后退出程序。下面新建一个 err.py 文件：

```python
def foo(s):
    return 10 / int(s)
def bar(s):
    return foo(s) * 2
def main():
    bar('0')

main()
```

执行结果：

```python
PS E:\Python3.6.3\workspace> python err.py
Traceback (most recent call last):
  File "err.py", line 8, in <module>
    main()
  File "err.py", line 6, in main
    bar('0')
  File "err.py", line 4, in bar
    return foo(s) * 2
  File "err.py", line 2, in foo
    return 10 / int(s)
ZeroDivisionError: division by zero
```

上面的信息我们可以看到整个错误的函数调用栈：

错误第一行：

```python
Traceback (most recent call last):
```

告诉我们以下是错误的跟踪信息。

第 2~3 行：

```python
File "err.py", line 8, in <module>
    main()
```

告诉我们 err.py 执行中，main () 出错了，在代码的第 8 行。

第 4~5 行：

```python
File "err.py", line 6, in main
    bar('0')
```

告诉我们错误原因是第 6 行代码。

依次往下，最终告诉我们是 foo 函数出错了：

```python
File "err.py", line 2, in foo
    return 10 / int(s)
```

这就是错误的源头，因为控制台打印了错误类型：

```python
ZeroDivisionError: division by zero
```

这是个 ZeroDivisionError，我们分析并不是 Int (s) 本身定义或者语法有错误，而是 int (s) 返回值为 0，从而找到了源头。

上面说了当我们在程序中不捕获错误的时候，python 解释器会在自动打印错误的堆栈，但是程序也会戛然而止。我们可以选择把错误堆栈打印出来，同时程序会继续执行下去。怎么操作呢？python 内置的 logging 模块可以非常清楚的记录错误信息，新建一个 err_logging.py 文件：

```python
import logging
def foo(s):
    return 10 / int(s)
def bar(s):
    return foo(s)*2
def main():
    try:
        bar('0')
    except Exception as e:
        logging.exception(e)

main()
print('最后执行了……')
```



```python

ERROR:root:division by zero
Traceback (most recent call last):
  File "err_logging.py", line 8, in main
    bar('0')
  File "err_logging.py", line 5, in bar
    return foo(s)*2
  File "err_logging.py", line 3, in foo
    return 10 / int(s)
ZeroDivisionError: division by zero
最后执行了……
```

同样出错了，但是程序处理完错误信息后会继续执行。

因为错误对象就是 class，其实我们自己也可以自定义错误用于抛出。

首先，应该定义一个错误的类，选择继承关系，然后用 raise 关键字抛出实例，创建一个 err_raise.py 文件：

```python
class FooError(ValueError):
    pass
def foo(s):
    n = int(s)
    if n == 0 :
        raise FooError('非法的数值:%s' % s)
    return 10 / n

foo('0')
```

执行后，如果有错误，我们可以追踪到自己定义的错误：

```python
PS E:\Python3.6.3\workspace> python err_raise.py
Traceback (most recent call last):
  File "err_raise.py", line 9, in <module>
    foo('0')
  File "err_raise.py", line 6, in foo
    raise FooError('非法的数值:%s' % s)
__main__.FooError: 非法的数值:0
```

有些时候我们会碰到一些当前代码不适合处理或者不能处理的错误，我可以选择记录下错误之后，在向上抛，这时在 except 代码块中加入 raise 语句。raise 语句还可以将错误类型转化。

[python 错误处理 —try…catch…finally、调用栈分析]:https://www.cnblogs.com/hiwuchong/p/8573081.html



[python 中的 try-catch-finally-else 简介]:https://blog.csdn.net/lwgkzl/article/details/81059433

